<!-- ======================================================

Model from https://github.com/deepmind/dm_control/blob/master/dm_control/suite/pendulum.xml

-->



<mujoco model="closed_chain">
  <compiler angle='degree' eulerseq='xyz' meshdir='stl'/>
  <include file="pendulum/visual.xml"/>
  <include file="pendulum/skybox.xml"/>
  <include file="pendulum/materials.xml"/>

  <option gravity='0 0 0.0' iterations='50' solver='Newton' timestep='0.000500'>
    <flag contact="disable" energy="enable"/>
  </option>

  <asset>
    <material name='collision' rgba='0.1 0.5 0.9 0.4'/>
    <material name='plane' reflectance='0.000000' texrepeat='1 1' texture='plane' texuniform='true'/>
    <material name='robot' rgba='0.9 0.5 0.1 1'/>
    <texture builtin='checker' height='512' name='plane' rgb1='0.2 0.2 0.2' rgb2='0.3 0.3 0.3' type='2d' width='512'/>
    <texture builtin='gradient' height='128' rgb1='0.4 0.6 0.8' rgb2='0 0 0' type='skybox' width='128'/>
    <mesh name='base' file='torso.stl'/>
    <mesh name='left-hip-roll' file='hip-yaw-housing.stl'/>
    <mesh name='left-hip-yaw' file='hip-pitch-housing.stl'/>
    <mesh name='left-hip-pitch' file='hip-pitch.stl'/>
    <mesh name='left-knee' file='knee.stl'/>
    <mesh name='left-shin' file='shin.stl'/>
    <mesh name='left-tarsus' file='tarsus.stl'/>
    <mesh name='left-toe-A' file='toe-output.stl'/>
    <mesh name='left-toe-A-rod' file='toe-A-rod.stl'/>
    <mesh name='left-toe-B' file='toe-output.stl'/>
    <mesh name='left-toe-B-rod' file='toe-B-rod.stl'/>
    <mesh name='left-toe-pitch' file='toe-pitch.stl'/>
    <mesh name='left-toe-roll' file='toe-roll.stl'/>
    <mesh name='left-heel-spring' file='heel-spring.stl'/>
    <mesh name='left-achillies-rod' file='achilles-rod.stl'/>
    <mesh name='right-hip-roll' scale='1 -1 1' file='hip-yaw-housing.stl'/>
    <mesh name='right-hip-yaw' scale='1 -1 1' file='hip-pitch-housing.stl'/>
    <mesh name='right-hip-pitch' scale='1 -1 1' file='hip-pitch.stl'/>
    <mesh name='right-knee' scale='1 -1 1' file='knee.stl'/>
    <mesh name='right-shin' scale='1 -1 1' file='shin.stl'/>
    <mesh name='right-tarsus' scale='1 -1 1' file='tarsus.stl'/>
    <mesh name='right-toe-A' scale='1 -1 1' file='toe-output.stl'/>
    <mesh name='right-toe-A-rod' scale='1 -1 1' file='toe-A-rod.stl'/>
    <mesh name='right-toe-B' scale='1 -1 1' file='toe-output.stl'/>
    <mesh name='right-toe-B-rod' scale='1 -1 1' file='toe-B-rod.stl'/>
    <mesh name='right-toe-pitch' scale='1 -1 1' file='toe-pitch.stl'/>
    <mesh name='right-toe-roll' scale='1 -1 1' file='toe-roll.stl'/>
    <mesh name='right-heel-spring' scale='1 -1 1' file='heel-spring.stl'/>
    <mesh name='right-achillies-rod' scale='1 -1 1' file='achilles-rod.stl'/>
    <mesh name='left-shoulder-roll' file='arm-L1.stl'/>
    <mesh name='left-shoulder-pitch' file='arm-L2.stl'/>
    <mesh name='left-shoulder-yaw' file='arm-L3.stl'/>
    <mesh name='left-elbow' file='arm-L4.stl'/>
    <mesh name='right-shoulder-roll' scale='1 -1 1' file='arm-L1.stl'/>
    <mesh name='right-shoulder-pitch' scale='1 -1 1' file='arm-L2.stl'/>
    <mesh name='right-shoulder-yaw' scale='1 -1 1' file='arm-L3.stl'/>
    <mesh name='right-elbow' scale='1 -1 1' file='arm-L4.stl'/>
  </asset>
  <default>
    <default class='collision'>
      <geom conaffinity='1' condim='3' contype='1' material='collision'/>
    </default>
    <default class='robot'>
      <geom material='robot'/>
    </default>
    <equality solref='0.005 1'/>
    <geom conaffinity='0' condim='1' contype='0' solref='0.005 1'/>
    <motor ctrllimited='true'/>
  </default>

  <worldbody>
    <light name="light" pos="0 0 2"/>
    <geom name="floor" size="2 2 .2" type="plane" material="grid"/>
    <camera name="fixed" pos="0 -1.5 2" xyaxes='1 0 0 0 1 1'/>
    <camera name="lookat" mode="targetbodycom" target="left-hip-pitch" pos="0 0 0"/>
    <body name='left-hip-pitch' pos='0 0.0 1' euler='90 0 -45'>
      <inertial pos='0.060537 0.000521 -0.038857' mass='6.244279' fullinertia='0.011533 0.033345 0.033958 -0.000171 0.000148 0.000178'/>
      <!--joint name='left-hip-pitch' type='hinge' axis='0 0 -1' range='-60 90' limited='true' damping='0' frictionloss='0' armature='0'/> -->
      <joint name='left-hip-pitch' type='hinge' axis='0 0 -1' range='-180 180' limited='true' damping='0' frictionloss='0' armature='0'/>
      <geom type='mesh' mesh='left-hip-pitch' material='robot'/>  
      <!-- geom type='cylinder' size ='0.05 0.072' pos='0 0 -0.04' euler='0 0 0' class='collision'/> -->
      <!-- geom type='cylinder' size ='0.05 0.072' pos='0.12 0 -0.04' euler='0 0 0' class='collision'/> -->
      <!--<geom type='box' size='0.06 0.05 0.072' pos='0.06 0 -0.04' euler='0 0 0' class='collision'/> -->
      <geom type='box' size='0.02 0.02 0.02' pos='0 0 0' euler='0 0 0'/>
      <!-- body name='left-achillies-rod' pos='0 0 0.046' euler='4.09 0.05 -82.27'> -->
      <body name='left-achillies-rod' pos='0 0 0.0' euler='0 0.05 -82.27'>
        <inertial pos='0.2506 0 0' mass='0.178148' fullinertia='3e-06 0.004501 0.004501 0 0 0'/>
        <joint name='left-achillies-rod' type='ball' limited='false' damping='0'/>
        <geom type='mesh' mesh='left-achillies-rod' material='robot'/>
        <!-- geom type='capsule' size ='0.007 0.25' pos='0.25 0 0' euler='4 90 0' class='collision'/> -->
      </body>
      <body name='left-knee' pos='0.12 0 0.0045' euler='0 0 -90'>
        <inertial pos='0.045641 0.042154 0.001657' mass='1.227077' fullinertia='0.002643 0.005098 0.007019 -0.001832 6.6e-05 4.5e-05'/>
        <!-- joint name='left-knee' type='hinge' axis='0 0 1' range='-71 50' limited='true' damping='0' frictionloss='0' armature='0'/> -->
        <joint name='left-knee' type='hinge' axis='0 0 1' range='-180 180' limited='true' damping='0' frictionloss='0' armature='0'/>
        <geom type='mesh' mesh='left-knee' material='robot'/> 
        <geom type='box' size='0.02 0.02 0.02' pos='0 0 0' euler='0 0 0'/>
        <body name='left-shin' pos='0.060677 0.047406 0' euler='0 0 0'>
          <inertial pos='0.174265 0.010265 0.00107' mass='0.895793' fullinertia='0.001128 0.022492 0.022793 0.001098 0.000196 -3e-06'/>
          <joint name='left-shin' type='hinge' axis='0 0 1' limited='false' stiffness='6000'/>
          <geom type='mesh' mesh='left-shin' material='robot'/>
          <!--geom type='cylinder' size ='0.03 0.1715' pos='0.23 0 0' euler='0 90 0' class='collision'/> -->
          <!-- geom type='cylinder' size ='0.05 0.1' pos='0.125 0.009 0' euler='90 84 0' class='collision'/> -->
          <geom type='box' size='0.02 0.02 0.02' pos='0 0 0' euler='0 0 0'/>
          <body name='left-tarsus' pos='0.434759 0.02 0' euler='0 0 103'>
            <inertial pos='0.100777 -0.029183 0.000678' mass='1.322865' fullinertia='0.000932 0.016409 0.016501 0.00061 0.000102 9e-06'/>
            <joint name='left-tarsus' type='hinge' axis='0 0 1' range='-50.3 71.6' limited='true'/>
            <geom type='mesh' mesh='left-tarsus' material='robot'/>
            <!-- geom type='capsule' size ='0.02 0.18' pos='0.21 -0.03 0' euler='0 90 0' class='collision'/> -->
            <geom type='box' size='0.02 0.02 0.02' pos='0 0 0' euler='0 0 0'/>
            <body name='left-heel-spring' pos='-0.01766 -0.029456 0.00104' euler='4.47 0.32 155.8'>
              <inertial pos='0.049086 0.004739 -4.5e-05' mass='0.230018' fullinertia='5.5e-05 0.00074 0.000701 1.5e-05 1e-06 -0'/>
              <joint name='left-heel-spring' type='hinge' axis='0 0 1' range='-6 6' limited='true' stiffness='4375'/>
              <geom type='box' size='0.02 0.02 0.02' pos='0 0 0' euler='0 0 0'/>
              <!--geom type='mesh' mesh='left-heel-spring' material='robot'/> -->
            </body>
          </body>
        </body>
      </body>
    </body>
  </worldbody>
  <equality>
    <!--connect name='left-achillies-rod' body1='left-heel-spring' body2='left-achillies-rod' anchor='0.113789 -0.011056 0'/> -->
    <!-- connect name='left-achillies-rod' body1='left-heel-spring' body2='left-achillies-rod' anchor='0.0 0.2 0.0'/> -->
  </equality>
  <actuator>
    <motor name='left-hip-pitch' joint='left-hip-pitch' gear='16' ctrllimited='true' ctrlrange='-50 50'/>
    <motor name='left-knee' joint='left-knee' gear='16' ctrllimited='true' ctrlrange='-50 50'/>
  </actuator>


</mujoco>
