<!-- ======================================================

Model from https://github.com/deepmind/dm_control/blob/master/dm_control/suite/pendulum.xml

-->



<mujoco model="pendulum">
  <include file="pendulum/visual.xml"/>
  <include file="pendulum/skybox.xml"/>
  <include file="pendulum/materials.xml"/>

  <option timestep="0.0001" gravity='0 0 -9.8' >
    <flag contact="disable" energy="enable"/>
  </option>

  <worldbody>
    <light name="light" pos="0 0 2"/>
    <geom name="floor" size="2 2 .2" type="plane" material="grid"/>
    <camera name="fixed" pos="0 -1.5 2" xyaxes='1 0 0 0 1 1'/>
    <camera name="lookat" mode="targetbodycom" target="pole" pos="0 -2 1"/>
    <body name="pole" pos="0 0 .5">
      <joint name="hinge" type="hinge" axis="0 -1 0" damping="0"/>
      <geom name="base" material="decoration" type="cylinder" fromto="0 -.03 0 0 .03 0" size="0.021" mass="0"/>
      <geom name="pole" material="self" type="capsule" fromto="0 0 0 0 0 0.5" size="0.02" mass="0"/>
      <geom name="mass" material="effector" type="sphere" pos="0 0 0.5" size="0.05" mass="1"/>
    </body>
  </worldbody>

  <actuator>
    <motor name="torque" joint="hinge" gear="2" ctrlrange="-100 100" ctrllimited="true"/>
  </actuator>
</mujoco>
